#### 1.Error实例对象   
javaScript解析或运行时，一旦发生错误，引擎就会抛出一个错误对象。JavaScript原生提供Error构造函数，所以抛出的错误都是这个构造函数的实例。
```
var err = new Error('出错了');
err.message  //'出错了'


//调用Error构造函数，生成一个实例对象err。Error构造函数接受一个参数，表示错误提示，可以从实例的message属性读到这个参数。抛出Error实例对象以后，整个程序就中断在发生错误的地方，不再往下执行。
```
Error实例对象属性参数
+ message：错误提示信息（必须）
+ name：错误名称（非标准属性）
+ stack：错误的堆栈（非标准属性）
> 使用name和message可以对发生什么错误有大概的了解;
> stack属性用来查看错误发生时的堆栈
```
if (error.name){
    console.log(error.name + ':' + error.message);
}
```

#### 2.原生错误类型
Error实例对象是最一般的错误类型。javaScript定义了其他6种错误对象（也称派生对象）。
+ **SyntaxError对象**：解析代码时发生的语法错误。
+ **ReferenceError对象**：引用一个不存在的变量时发生的错误。
+ **RangeError对象**：一个值超出有效范围时发生的错误。（主要有几种情况，一是数组长度为负数，二是Number对象的方法参数超出范围，以及函数堆栈超过最大值）
+ **TypeError对象**：变量或参数不是预期类型时发生的错误。比如，对字符串、布尔值、数值等原始类型的值使用new命令，就会抛出这样的错误，因为new命令应该是一个构造函数。
+ **URIError对象**：URI相关函数的参数不正确时抛出的错误，主要涉及encodeURI()、decodeURI()、encodeURIComponent()、escape() 和unescape()这六个函数。
+ **EvalError对象**：eval函数没有被正确执行时，会抛出EvalError错误。该错误类型已经不再使用了，只是为了保证与以前代码兼容，才继续保留。

总结：以上6种派生错误，联通原始的Error对象，都是构造函数。开发者可以使用它们，手动生成错误对象的实例。
```
var err1 = new Error('出错了')
var err2 = new RangeError（'出错了，变量超出有效范围！'）
var err3 = new TypeError('出错了，变量类型无效！')

err1.message // "出错了！"
err2.message // "出错了，变量超出有效范围！"
err3.message // "出错了，变量类型无效！"
```

#### 3.自定义错误
除了以上介绍的7种错误对象，还可以自己定义错误对象。
```
function UserError(message){
    this.message = message || '默认信息';
    this.name = 'UserError';
}

UserError.prototype = new Error();
UserError.prototype.constructor = UserError;

//错误对象UserError,继承Error对象，然后可以生成自定义类型的错误了

new UserError('这是自定义的错误对象！');

```

#### 4.throw语句   
手动中断程序执行，抛出一个错误。
```
if (x <= 0) {
  throw new Error('x 必须为正数');
}
// Uncaught ReferenceError: x is not defined
```
对于javaScript引擎来说，遇到throw语句，程序就中止了。引擎会接收到throw抛出的信息，可能是错误实例，也可能是其他类型的值。

#### 5.try...catch结构    
一旦发生错误，程序就中止执行了。JavaScript提供了try...catch结构，允许对错误进行处理，选择是否往下执行。
```
try {
  throw new Error('出错了!');
} catch (e) {
  console.log(e.name + ": " + e.message);
  console.log(e.stack);
}
//try代码抛出错误，然后catch捕获错误，对错误进行处理。
```

#### 6.finally代码块
允许在最后添加一个finally代码块，表示不管是否出现错误，都必需在最后运行的语句。
```
function cleansUp() {
  try {
    throw new Error('出错了……');
    console.log('此行不会执行');
  } finally {
    console.log('完成清理工作');
  }
}

cleansUp()
// 完成清理工作
// Uncaught Error: 出错了……
//    at cleansUp (<anonymous>:3:11)
//    at <anonymous>:10:1
```

## 完结 2019/7/13